using System;
using System.Threading.Tasks;
using Jasper.ErrorHandling;
using Jasper.Tracking;
using TestingSupport.ErrorHandling;
using Xunit;

namespace Jasper.Testing.ErrorHandling
{
    public class Fallback_from_Chain_to_Global_Error_Handling : ErrorHandlingContext
    {
        public Fallback_from_Chain_to_Global_Error_Handling()
        {
            theOptions.Handlers.OnException<DivideByZeroException>().RetryNow();
            theOptions.Handlers.OnException<DataMisalignedException>().Requeue();
            theOptions.Handlers.OnException<DataMisalignedException>().MoveToErrorQueue();

            theOptions.Handlers.ConfigureHandlerForMessage<ErrorCausingMessage>(chain =>
            {
                chain.OnException<DivideByZeroException>().MoveToErrorQueue();
                chain.OnException<InvalidOperationException>().RetryNow();
                chain.Retries.MaximumAttempts = 3;
            });

        }

        [Fact]
        public async Task chain_specific_rules_do_not_apply()
        {
            throwOnAttempt<DataMisalignedException>(1);
            throwOnAttempt<DataMisalignedException>(2);

            var record = await afterProcessingIsComplete();

            record.ShouldHaveSucceededOnAttempt(3);
        }

        [Fact]
        public async Task chain_specific_rules_catch()
        {
            throwOnAttempt<DivideByZeroException>(1);

            await shouldMoveToErrorQueueOnAttempt(1);
        }

        [Fact]
        public async Task chain_specific_rules_win_again()
        {
            throwOnAttempt<InvalidOperationException>(1);

            await shouldSucceedOnAttempt(2);
        }
    }
}
